2021-07-18 17:19:29,333 asyncio      DEBUG    Using proactor: IocpProactor
2021-07-18 17:19:50,321 asyncio      DEBUG    Using proactor: IocpProactor
2021-07-18 17:20:42,259 django.utils.autoreload INFO     Watching for file changes with StatReloader
2021-07-18 17:22:56,208 django.request WARNING  Not Found: /favicon.ico
2021-07-18 17:24:15,854 django.utils.autoreload INFO     C:\Users\RUPALI\PycharmProjects\DjangoLogging\LoggerProject\urls.py changed, reloading.
2021-07-18 17:24:15,854 asyncio      DEBUG    Using proactor: IocpProactor
2021-07-18 17:24:20,573 django.utils.autoreload INFO     Watching for file changes with StatReloader
2021-07-18 17:28:09,309 asyncio      DEBUG    Using proactor: IocpProactor
2021-07-18 17:28:09,445 asyncio      DEBUG    Using proactor: IocpProactor
2021-07-18 17:28:13,285 django.utils.autoreload INFO     Watching for file changes with StatReloader
2021-07-18 17:28:19,277 django.request WARNING  Not Found: /
2021-07-18 17:30:41,352 django.request ERROR    Internal Server Error: /view/
Traceback (most recent call last):
  File "C:\Users\RUPALI\PycharmProjects\DjangoLogging\venv\lib\site-packages\django\core\handlers\exception.py", line 47, in inner
    response = get_response(request)
  File "C:\Users\RUPALI\PycharmProjects\DjangoLogging\venv\lib\site-packages\django\core\handlers\base.py", line 181, in _get_response
    response = wrapped_callback(request, *callback_args, **callback_kwargs)
  File "C:\Users\RUPALI\PycharmProjects\DjangoLogging\venv\lib\site-packages\django\views\decorators\csrf.py", line 54, in wrapped_view
    return view_func(*args, **kwargs)
  File "C:\Users\RUPALI\PycharmProjects\DjangoLogging\venv\lib\site-packages\django\views\generic\base.py", line 70, in view
    return self.dispatch(request, *args, **kwargs)
  File "C:\Users\RUPALI\PycharmProjects\DjangoLogging\venv\lib\site-packages\rest_framework\views.py", line 509, in dispatch
    response = self.handle_exception(exc)
  File "C:\Users\RUPALI\PycharmProjects\DjangoLogging\venv\lib\site-packages\rest_framework\views.py", line 469, in handle_exception
    self.raise_uncaught_exception(exc)
  File "C:\Users\RUPALI\PycharmProjects\DjangoLogging\venv\lib\site-packages\rest_framework\views.py", line 480, in raise_uncaught_exception
    raise exc
  File "C:\Users\RUPALI\PycharmProjects\DjangoLogging\venv\lib\site-packages\rest_framework\views.py", line 506, in dispatch
    response = handler(request, *args, **kwargs)
  File "C:\Users\RUPALI\PycharmProjects\DjangoLogging\logapp\views.py", line 26, in post
    student_name = serializer.data.get('s_name'),
  File "C:\Users\RUPALI\PycharmProjects\DjangoLogging\venv\lib\site-packages\rest_framework\serializers.py", line 548, in data
    ret = super().data
  File "C:\Users\RUPALI\PycharmProjects\DjangoLogging\venv\lib\site-packages\rest_framework\serializers.py", line 242, in data
    raise AssertionError(msg)
AssertionError: When a serializer is passed a `data` keyword argument you must call `.is_valid()` before attempting to access the serialized `.data` representation.
You should either call `.is_valid()` first, or access `.initial_data` instead.
2021-07-18 17:31:53,578 django.utils.autoreload INFO     C:\Users\RUPALI\PycharmProjects\DjangoLogging\logapp\views.py changed, reloading.
2021-07-18 17:31:53,608 asyncio      DEBUG    Using proactor: IocpProactor
2021-07-18 17:31:54,516 django.utils.autoreload INFO     Watching for file changes with StatReloader
2021-07-18 17:33:25,005 django.request ERROR    Internal Server Error: /view/
Traceback (most recent call last):
  File "C:\Users\RUPALI\PycharmProjects\DjangoLogging\venv\lib\site-packages\django\core\handlers\exception.py", line 47, in inner
    response = get_response(request)
  File "C:\Users\RUPALI\PycharmProjects\DjangoLogging\venv\lib\site-packages\django\core\handlers\base.py", line 181, in _get_response
    response = wrapped_callback(request, *callback_args, **callback_kwargs)
  File "C:\Users\RUPALI\PycharmProjects\DjangoLogging\venv\lib\site-packages\django\views\decorators\csrf.py", line 54, in wrapped_view
    return view_func(*args, **kwargs)
  File "C:\Users\RUPALI\PycharmProjects\DjangoLogging\venv\lib\site-packages\django\views\generic\base.py", line 70, in view
    return self.dispatch(request, *args, **kwargs)
  File "C:\Users\RUPALI\PycharmProjects\DjangoLogging\venv\lib\site-packages\rest_framework\views.py", line 509, in dispatch
    response = self.handle_exception(exc)
  File "C:\Users\RUPALI\PycharmProjects\DjangoLogging\venv\lib\site-packages\rest_framework\views.py", line 469, in handle_exception
    self.raise_uncaught_exception(exc)
  File "C:\Users\RUPALI\PycharmProjects\DjangoLogging\venv\lib\site-packages\rest_framework\views.py", line 480, in raise_uncaught_exception
    raise exc
  File "C:\Users\RUPALI\PycharmProjects\DjangoLogging\venv\lib\site-packages\rest_framework\views.py", line 506, in dispatch
    response = handler(request, *args, **kwargs)
  File "C:\Users\RUPALI\PycharmProjects\DjangoLogging\logapp\views.py", line 27, in post
    student_name = serializer.data.get('s_name'),
  File "C:\Users\RUPALI\PycharmProjects\DjangoLogging\venv\lib\site-packages\rest_framework\serializers.py", line 548, in data
    ret = super().data
  File "C:\Users\RUPALI\PycharmProjects\DjangoLogging\venv\lib\site-packages\rest_framework\serializers.py", line 242, in data
    raise AssertionError(msg)
AssertionError: When a serializer is passed a `data` keyword argument you must call `.is_valid()` before attempting to access the serialized `.data` representation.
You should either call `.is_valid()` first, or access `.initial_data` instead.
2021-07-18 17:36:52,306 django.utils.autoreload INFO     C:\Users\RUPALI\PycharmProjects\DjangoLogging\logapp\views.py changed, reloading.
2021-07-18 17:36:52,433 asyncio      DEBUG    Using proactor: IocpProactor
2021-07-18 17:36:59,217 django.utils.autoreload INFO     Watching for file changes with StatReloader
2021-07-18 17:38:36,321 django.request ERROR    Internal Server Error: /view/
Traceback (most recent call last):
  File "C:\Users\RUPALI\PycharmProjects\DjangoLogging\venv\lib\site-packages\django\core\handlers\exception.py", line 47, in inner
    response = get_response(request)
  File "C:\Users\RUPALI\PycharmProjects\DjangoLogging\venv\lib\site-packages\django\core\handlers\base.py", line 181, in _get_response
    response = wrapped_callback(request, *callback_args, **callback_kwargs)
  File "C:\Users\RUPALI\PycharmProjects\DjangoLogging\venv\lib\site-packages\django\views\decorators\csrf.py", line 54, in wrapped_view
    return view_func(*args, **kwargs)
  File "C:\Users\RUPALI\PycharmProjects\DjangoLogging\venv\lib\site-packages\django\views\generic\base.py", line 70, in view
    return self.dispatch(request, *args, **kwargs)
  File "C:\Users\RUPALI\PycharmProjects\DjangoLogging\venv\lib\site-packages\rest_framework\views.py", line 509, in dispatch
    response = self.handle_exception(exc)
  File "C:\Users\RUPALI\PycharmProjects\DjangoLogging\venv\lib\site-packages\rest_framework\views.py", line 469, in handle_exception
    self.raise_uncaught_exception(exc)
  File "C:\Users\RUPALI\PycharmProjects\DjangoLogging\venv\lib\site-packages\rest_framework\views.py", line 480, in raise_uncaught_exception
    raise exc
  File "C:\Users\RUPALI\PycharmProjects\DjangoLogging\venv\lib\site-packages\rest_framework\views.py", line 506, in dispatch
    response = handler(request, *args, **kwargs)
  File "C:\Users\RUPALI\PycharmProjects\DjangoLogging\logapp\views.py", line 25, in post
    obj = Student.objects.create(
  File "C:\Users\RUPALI\PycharmProjects\DjangoLogging\venv\lib\site-packages\django\db\models\manager.py", line 85, in manager_method
    return getattr(self.get_queryset(), name)(*args, **kwargs)
  File "C:\Users\RUPALI\PycharmProjects\DjangoLogging\venv\lib\site-packages\django\db\models\query.py", line 451, in create
    obj = self.model(**kwargs)
  File "C:\Users\RUPALI\PycharmProjects\DjangoLogging\venv\lib\site-packages\django\db\models\base.py", line 503, in __init__
    raise TypeError("%s() got an unexpected keyword argument '%s'" % (cls.__name__, kwarg))
TypeError: Student() got an unexpected keyword argument 'student_name'
2021-07-18 17:39:38,723 django.utils.autoreload INFO     C:\Users\RUPALI\PycharmProjects\DjangoLogging\logapp\views.py changed, reloading.
2021-07-18 17:39:38,724 asyncio      DEBUG    Using proactor: IocpProactor
2021-07-18 17:39:39,894 django.utils.autoreload INFO     Watching for file changes with StatReloader
2021-07-18 17:39:56,332 django.request ERROR    Internal Server Error: /view/
Traceback (most recent call last):
  File "C:\Users\RUPALI\PycharmProjects\DjangoLogging\venv\lib\site-packages\django\core\handlers\exception.py", line 47, in inner
    response = get_response(request)
  File "C:\Users\RUPALI\PycharmProjects\DjangoLogging\venv\lib\site-packages\django\core\handlers\base.py", line 204, in _get_response
    response = response.render()
  File "C:\Users\RUPALI\PycharmProjects\DjangoLogging\venv\lib\site-packages\django\template\response.py", line 105, in render
    self.content = self.rendered_content
  File "C:\Users\RUPALI\PycharmProjects\DjangoLogging\venv\lib\site-packages\rest_framework\response.py", line 70, in rendered_content
    ret = renderer.render(self.data, accepted_media_type, context)
  File "C:\Users\RUPALI\PycharmProjects\DjangoLogging\venv\lib\site-packages\rest_framework\renderers.py", line 724, in render
    context = self.get_context(data, accepted_media_type, renderer_context)
  File "C:\Users\RUPALI\PycharmProjects\DjangoLogging\venv\lib\site-packages\rest_framework\renderers.py", line 680, in get_context
    'content': self.get_content(renderer, data, accepted_media_type, renderer_context),
  File "C:\Users\RUPALI\PycharmProjects\DjangoLogging\venv\lib\site-packages\rest_framework\renderers.py", line 413, in get_content
    content = renderer.render(data, accepted_media_type, renderer_context)
  File "C:\Users\RUPALI\PycharmProjects\DjangoLogging\venv\lib\site-packages\rest_framework\renderers.py", line 100, in render
    ret = json.dumps(
  File "C:\Users\RUPALI\PycharmProjects\DjangoLogging\venv\lib\site-packages\rest_framework\utils\json.py", line 25, in dumps
    return json.dumps(*args, **kwargs)
  File "C:\Users\RUPALI\AppData\Local\Programs\Python\Python39\lib\json\__init__.py", line 234, in dumps
    return cls(
  File "C:\Users\RUPALI\AppData\Local\Programs\Python\Python39\lib\json\encoder.py", line 201, in encode
    chunks = list(chunks)
  File "C:\Users\RUPALI\AppData\Local\Programs\Python\Python39\lib\json\encoder.py", line 431, in _iterencode
    yield from _iterencode_dict(o, _current_indent_level)
  File "C:\Users\RUPALI\AppData\Local\Programs\Python\Python39\lib\json\encoder.py", line 405, in _iterencode_dict
    yield from chunks
  File "C:\Users\RUPALI\AppData\Local\Programs\Python\Python39\lib\json\encoder.py", line 438, in _iterencode
    o = _default(o)
  File "C:\Users\RUPALI\PycharmProjects\DjangoLogging\venv\lib\site-packages\rest_framework\utils\encoders.py", line 67, in default
    return super().default(obj)
  File "C:\Users\RUPALI\AppData\Local\Programs\Python\Python39\lib\json\encoder.py", line 179, in default
    raise TypeError(f'Object of type {o.__class__.__name__} '
TypeError: Object of type Student is not JSON serializable
2021-07-18 17:41:56,021 django.utils.autoreload INFO     C:\Users\RUPALI\PycharmProjects\DjangoLogging\logapp\views.py changed, reloading.
2021-07-18 17:41:56,040 asyncio      DEBUG    Using proactor: IocpProactor
2021-07-18 17:41:57,923 django.utils.autoreload INFO     Watching for file changes with StatReloader
2021-07-18 17:42:01,715 django.utils.autoreload INFO     C:\Users\RUPALI\PycharmProjects\DjangoLogging\logapp\views.py changed, reloading.
2021-07-18 17:42:01,717 asyncio      DEBUG    Using proactor: IocpProactor
2021-07-18 17:42:02,432 django.utils.autoreload INFO     Watching for file changes with StatReloader
2021-07-18 17:42:14,770 django.utils.autoreload INFO     C:\Users\RUPALI\PycharmProjects\DjangoLogging\logapp\views.py changed, reloading.
2021-07-18 17:42:14,772 asyncio      DEBUG    Using proactor: IocpProactor
2021-07-18 17:42:15,793 django.utils.autoreload INFO     Watching for file changes with StatReloader
2021-07-18 17:42:25,790 django.utils.autoreload INFO     C:\Users\RUPALI\PycharmProjects\DjangoLogging\logapp\views.py changed, reloading.
2021-07-18 17:42:25,792 asyncio      DEBUG    Using proactor: IocpProactor
2021-07-18 17:42:26,449 django.utils.autoreload INFO     Watching for file changes with StatReloader
2021-07-18 17:42:33,257 django.utils.autoreload INFO     C:\Users\RUPALI\PycharmProjects\DjangoLogging\logapp\views.py changed, reloading.
2021-07-18 17:42:33,258 asyncio      DEBUG    Using proactor: IocpProactor
2021-07-18 17:42:34,066 django.utils.autoreload INFO     Watching for file changes with StatReloader
2021-07-18 17:42:44,101 django.utils.autoreload INFO     C:\Users\RUPALI\PycharmProjects\DjangoLogging\logapp\views.py changed, reloading.
2021-07-18 17:42:44,102 asyncio      DEBUG    Using proactor: IocpProactor
2021-07-18 17:42:44,790 django.utils.autoreload INFO     Watching for file changes with StatReloader
2021-07-18 17:43:45,177 django.request ERROR    Internal Server Error: /view/
Traceback (most recent call last):
  File "C:\Users\RUPALI\PycharmProjects\DjangoLogging\venv\lib\site-packages\django\core\handlers\exception.py", line 47, in inner
    response = get_response(request)
  File "C:\Users\RUPALI\PycharmProjects\DjangoLogging\venv\lib\site-packages\django\core\handlers\base.py", line 181, in _get_response
    response = wrapped_callback(request, *callback_args, **callback_kwargs)
  File "C:\Users\RUPALI\PycharmProjects\DjangoLogging\venv\lib\site-packages\django\views\decorators\csrf.py", line 54, in wrapped_view
    return view_func(*args, **kwargs)
  File "C:\Users\RUPALI\PycharmProjects\DjangoLogging\venv\lib\site-packages\django\views\generic\base.py", line 70, in view
    return self.dispatch(request, *args, **kwargs)
  File "C:\Users\RUPALI\PycharmProjects\DjangoLogging\venv\lib\site-packages\rest_framework\views.py", line 509, in dispatch
    response = self.handle_exception(exc)
  File "C:\Users\RUPALI\PycharmProjects\DjangoLogging\venv\lib\site-packages\rest_framework\views.py", line 469, in handle_exception
    self.raise_uncaught_exception(exc)
  File "C:\Users\RUPALI\PycharmProjects\DjangoLogging\venv\lib\site-packages\rest_framework\views.py", line 480, in raise_uncaught_exception
    raise exc
  File "C:\Users\RUPALI\PycharmProjects\DjangoLogging\venv\lib\site-packages\rest_framework\views.py", line 506, in dispatch
    response = handler(request, *args, **kwargs)
  File "C:\Users\RUPALI\PycharmProjects\DjangoLogging\logapp\views.py", line 32, in post
    serializer.save()
  File "C:\Users\RUPALI\PycharmProjects\DjangoLogging\venv\lib\site-packages\rest_framework\serializers.py", line 173, in save
    assert hasattr(self, '_errors'), (
AssertionError: You must call `.is_valid()` before calling `.save()`.
2021-07-18 17:44:15,867 django.utils.autoreload INFO     C:\Users\RUPALI\PycharmProjects\DjangoLogging\logapp\views.py changed, reloading.
2021-07-18 17:44:15,868 asyncio      DEBUG    Using proactor: IocpProactor
2021-07-18 17:44:16,512 django.utils.autoreload INFO     Watching for file changes with StatReloader
2021-07-18 17:44:41,142 django.request ERROR    Internal Server Error: /view/
Traceback (most recent call last):
  File "C:\Users\RUPALI\PycharmProjects\DjangoLogging\venv\lib\site-packages\django\core\handlers\exception.py", line 47, in inner
    response = get_response(request)
  File "C:\Users\RUPALI\PycharmProjects\DjangoLogging\venv\lib\site-packages\django\core\handlers\base.py", line 181, in _get_response
    response = wrapped_callback(request, *callback_args, **callback_kwargs)
  File "C:\Users\RUPALI\PycharmProjects\DjangoLogging\venv\lib\site-packages\django\views\decorators\csrf.py", line 54, in wrapped_view
    return view_func(*args, **kwargs)
  File "C:\Users\RUPALI\PycharmProjects\DjangoLogging\venv\lib\site-packages\django\views\generic\base.py", line 70, in view
    return self.dispatch(request, *args, **kwargs)
  File "C:\Users\RUPALI\PycharmProjects\DjangoLogging\venv\lib\site-packages\rest_framework\views.py", line 509, in dispatch
    response = self.handle_exception(exc)
  File "C:\Users\RUPALI\PycharmProjects\DjangoLogging\venv\lib\site-packages\rest_framework\views.py", line 469, in handle_exception
    self.raise_uncaught_exception(exc)
  File "C:\Users\RUPALI\PycharmProjects\DjangoLogging\venv\lib\site-packages\rest_framework\views.py", line 480, in raise_uncaught_exception
    raise exc
  File "C:\Users\RUPALI\PycharmProjects\DjangoLogging\venv\lib\site-packages\rest_framework\views.py", line 506, in dispatch
    response = handler(request, *args, **kwargs)
  File "C:\Users\RUPALI\PycharmProjects\DjangoLogging\logapp\views.py", line 33, in post
    return Response({"message": "Data saved successfully", "status": status.HTTP_201_CREATED, "result": obj})
NameError: name 'obj' is not defined
2021-07-18 17:45:01,176 django.utils.autoreload INFO     C:\Users\RUPALI\PycharmProjects\DjangoLogging\logapp\views.py changed, reloading.
2021-07-18 17:45:01,178 asyncio      DEBUG    Using proactor: IocpProactor
2021-07-18 17:45:02,225 django.utils.autoreload INFO     Watching for file changes with StatReloader
2021-07-18 17:46:08,942 django.utils.autoreload INFO     C:\Users\RUPALI\PycharmProjects\DjangoLogging\logapp\views.py changed, reloading.
2021-07-18 17:46:08,943 asyncio      DEBUG    Using proactor: IocpProactor
2021-07-18 17:46:09,719 django.utils.autoreload INFO     Watching for file changes with StatReloader
2021-07-18 17:47:53,452 django.utils.autoreload INFO     C:\Users\RUPALI\PycharmProjects\DjangoLogging\logapp\views.py changed, reloading.
2021-07-18 17:47:53,455 asyncio      DEBUG    Using proactor: IocpProactor
2021-07-18 17:47:54,329 django.utils.autoreload INFO     Watching for file changes with StatReloader
2021-07-18 17:48:48,016 django.utils.autoreload INFO     C:\Users\RUPALI\PycharmProjects\DjangoLogging\logapp\views.py changed, reloading.
2021-07-18 17:48:48,017 asyncio      DEBUG    Using proactor: IocpProactor
2021-07-18 17:48:48,907 django.utils.autoreload INFO     Watching for file changes with StatReloader
2021-07-18 20:40:12,015 asyncio      DEBUG    Using proactor: IocpProactor
